<mujoco model="solo">
    <compiler angle="radian" meshdir="../meshes/"/>
    <visual>
        <map znear="0.02"/>
    </visual>
    <option timestep="0.002"/>
    <worldbody>
        <light cutoff="100" diffuse="1 1 1" dir="-0 0 -1.3" directional="true" exponent="1" pos="0 0 1.3" specular=".1 .1 .1"/>
        <geom conaffinity="1" condim="3" name="floor" pos="0 0 0" rgba="0.8 0.9 0.8 1" size="20 20 .125" type="plane" material="MatPlane"/>
        <body name="SOLO" pos="0 0 .5">
            <freejoint name="root"/>
            <geom type="mesh" contype="0" conaffinity="0" group="1" rgba="0.8 0.8 0.8 1" mesh="solo_12_base" />
            <geom type="mesh" rgba="0.8 0.8 0.8 1" mesh="solo_12_base" />
            <body name="FL_SHOULDER" pos="0.1946 0.0875 0">
                <inertial pos="-0.078707 0.01 0" quat="0.529086 0.529086 0.469114 0.469114" mass="0.148538" diaginertia="0.000417563 0.00041107 2.46069e-05" />
                <joint name="FL_HAA" pos="0 0 0" axis="1 0 0" limited="true" range="-10 10"  stiffness=".01" type="hinge"/>
                <geom pos="0.0195 0 0" type="mesh" contype="0" conaffinity="0" group="1" rgba="0.8 0.8 0.8 1" mesh="solo12_hip_fe_fl" />
                <geom pos="0.0195 0 0" type="mesh" rgba="0.8 0.8 0.8 1" mesh="solo12_hip_fe_fl" />
                <body name="FL_UPPER_LEG" pos="0 0.014 0">
                    <inertial pos="1.377e-05 0.0193585 -0.078707" quat="0.705834 0.0424071 -0.0424071 0.705834" mass="0.148538" diaginertia="0.000417563 0.00041107 2.46069e-05" />
                    <joint name="FL_HFE" pos="0 0 0" axis="0 1 0" limited="true" range="-10 10"  stiffness=".01" type="hinge"/>
                    <geom type="mesh" contype="0" conaffinity="0" group="1" rgba="0.8 0.8 0.8 1" mesh="solo_upper_leg_left_side" />
                    <geom type="mesh" rgba="0.8 0.8 0.8 1" mesh="solo_upper_leg_left_side" />
                    <body name="FL_LOWER_LEG" pos="0 0.03745 -0.16">
                        <inertial pos="0 0.00789921 -0.102249" quat="0.707067 0.00747737 -0.00747737 0.707067" mass="0.0376361" diaginertia="0.000149205 0.000148819 2.62453e-06" />
                        <joint name="FL_KFE" pos="0 0 0" axis="0 1 0" limited="true" range="-10 10"  stiffness=".01" type="hinge" />
                        <geom type="mesh" contype="0" conaffinity="0" group="1" rgba="0.8 0.8 0.8 1" mesh="solo_lower_leg_left_side" />
                        <geom type="mesh" rgba="0.8 0.8 0.8 1" mesh="solo_lower_leg_left_side" />
                        <geom pos="0 0.008 -0.16" type="mesh" contype="0" conaffinity="0" group="1" rgba="0.8 0.8 0.8 1" mesh="solo_foot" />
                        <geom pos="0 0.008 -0.16" type="mesh" rgba="0.8 0.8 0.8 1" mesh="solo_foot" />
                    </body>
                </body>
            </body>
            <body name="FR_SHOULDER" pos="0.1946 -0.0875 0">
                <inertial pos="-0.078707 -0.01 0" quat="0.469114 0.469114 0.529086 0.529086" mass="0.148538" diaginertia="0.000417563 0.00041107 2.46069e-05" />
                <joint name="FR_HAA" pos="0 0 0" axis="1 0 0" limited="true" range="-10 10"  stiffness=".01" type="hinge" />
                <geom pos="0.0195 0 0" type="mesh" contype="0" conaffinity="0" group="1" rgba="0.8 0.8 0.8 1" mesh="solo12_hip_fe_fr" />
                <geom pos="0.0195 0 0" type="mesh" rgba="0.8 0.8 0.8 1" mesh="solo12_hip_fe_fr" />
                <body name="FR_UPPER_LEG" pos="0 -0.014 0">
                    <inertial pos="-1.377e-05 -0.0193585 -0.078707" quat="0.705834 -0.0424071 0.0424071 0.705834" mass="0.148538" diaginertia="0.000417563 0.00041107 2.46069e-05" />
                    <joint name="FR_HFE" pos="0 0 0" axis="0 1 0" limited="true" range="-10 10"  stiffness=".01" type="hinge" />
                    <geom type="mesh" contype="0" conaffinity="0" group="1" rgba="0.8 0.8 0.8 1" mesh="solo_upper_leg_right_side" />
                    <geom type="mesh" rgba="0.8 0.8 0.8 1" mesh="solo_upper_leg_right_side" />
                    <body name="FR_LOWER_LEG" pos="0 -0.03745 -0.16">
                        <inertial pos="0 0.00495053 -0.102249" quat="0.999484 -0.0321221 0 0" mass="0.0376361" diaginertia="0.000150245 0.000149742 3.5132e-06" />
                        <joint name="FR_KFE" pos="0 0 0" axis="0 1 0" limited="true" range="-10 10"  stiffness=".01" type="hinge" />
                        <geom type="mesh" contype="0" conaffinity="0" group="1" rgba="0.8 0.8 0.8 1" mesh="solo_lower_leg_right_side" />
                        <geom type="mesh" rgba="0.8 0.8 0.8 1" mesh="solo_lower_leg_right_side" />
                        <geom pos="0 -0.008 -0.16" type="mesh" contype="0" conaffinity="0" group="1" rgba="0.8 0.8 0.8 1" mesh="solo_foot" />
                        <geom pos="0 -0.008 -0.16" type="mesh" rgba="0.8 0.8 0.8 1" mesh="solo_foot" />
                    </body>
                </body>
            </body>
            <body name="HL_SHOULDER" pos="-0.1946 0.0875 0">
                <inertial pos="0.078707 0.01 0" quat="0.529086 0.529086 0.469114 0.469114" mass="0.148538" diaginertia="0.000417563 0.00041107 2.46069e-05" />
                <joint name="HL_HAA" pos="0 0 0" axis="1 0 0" limited="true" range="-10 10"  stiffness=".01" type="hinge" />
                <geom pos="-0.0195 0 0" type="mesh" contype="0" conaffinity="0" group="1" rgba="0.8 0.8 0.8 1" mesh="solo12_hip_fe_hl" />
                <geom pos="-0.0195 0 0" type="mesh" rgba="0.8 0.8 0.8 1" mesh="solo12_hip_fe_hl" />
                <body name="HL_UPPER_LEG" pos="0 0.014 0">
                    <inertial pos="1.377e-05 0.0193585 -0.078707" quat="0.705834 0.0424071 -0.0424071 0.705834" mass="0.148538" diaginertia="0.000417563 0.00041107 2.46069e-05" />
                    <joint name="HL_HFE" pos="0 0 0" axis="0 1 0" limited="true" range="-10 10"  stiffness=".01" type="hinge" />
                    <geom type="mesh" contype="0" conaffinity="0" group="1" rgba="0.8 0.8 0.8 1" mesh="solo_upper_leg_left_side" />
                    <geom type="mesh" rgba="0.8 0.8 0.8 1" mesh="solo_upper_leg_left_side" />
                    <body name="HL_LOWER_LEG" pos="0 0.03745 -0.16">
                        <inertial pos="0 0.00789921 -0.102249" quat="0.707067 0.00747737 -0.00747737 0.707067" mass="0.0376361" diaginertia="0.000149205 0.000148819 2.62453e-06" />
                        <joint name="HL_KFE" pos="0 0 0" axis="0 1 0" limited="true" range="-10 10"  stiffness=".01" type="hinge" />
                        <geom type="mesh" contype="0" conaffinity="0" group="1" rgba="0.8 0.8 0.8 1" mesh="solo_lower_leg_left_side" />
                        <geom type="mesh" rgba="0.8 0.8 0.8 1" mesh="solo_lower_leg_left_side" />
                        <geom pos="0 0.008 -0.16" type="mesh" contype="0" conaffinity="0" group="1" rgba="0.8 0.8 0.8 1" mesh="solo_foot" />
                        <geom pos="0 0.008 -0.16" type="mesh" rgba="0.8 0.8 0.8 1" mesh="solo_foot" />
                    </body>
                </body>
            </body>
            <body name="HR_SHOULDER" pos="-0.1946 -0.0875 0">
                <inertial pos="0.078707 -0.01 0" quat="0.469114 0.469114 0.529086 0.529086" mass="0.148538" diaginertia="0.000417563 0.00041107 2.46069e-05" />
                <joint name="HR_HAA" pos="0 0 0" axis="1 0 0" limited="true" range="-10 10"  stiffness=".01" type="hinge" />
                <geom pos="-0.0195 0 0" type="mesh" contype="0" conaffinity="0" group="1" rgba="0.8 0.8 0.8 1" mesh="solo12_hip_fe_hr" />
                <geom pos="-0.0195 0 0" type="mesh" rgba="0.8 0.8 0.8 1" mesh="solo12_hip_fe_hr" />
                <body name="HR_UPPER_LEG" pos="0 -0.014 0">
                    <inertial pos="-1.377e-05 -0.0193585 -0.078707" quat="0.705834 -0.0424071 0.0424071 0.705834" mass="0.148538" diaginertia="0.000417563 0.00041107 2.46069e-05" />
                    <joint name="HR_HFE" pos="0 0 0" axis="0 1 0" limited="true" range="-10 10"  stiffness=".01" type="hinge" />
                    <geom type="mesh" contype="0" conaffinity="0" group="1" rgba="0.8 0.8 0.8 1" mesh="solo_upper_leg_right_side" />
                    <geom type="mesh" rgba="0.8 0.8 0.8 1" mesh="solo_upper_leg_right_side" />
                    <body name="HR_LOWER_LEG" pos="0 -0.03745 -0.16">
                        <inertial pos="0 0.00495053 -0.102249" quat="0.999484 -0.0321221 0 0" mass="0.0376361" diaginertia="0.000150245 0.000149742 3.5132e-06" />
                        <joint name="HR_KFE" pos="0 0 0" axis="0 1 0" limited="true" range="-10 10"  stiffness=".01" type="hinge" />
                        <geom type="mesh" contype="0" conaffinity="0" group="1" rgba="0.8 0.8 0.8 1" mesh="solo_lower_leg_right_side" />
                        <geom type="mesh" rgba="0.8 0.8 0.8 1" mesh="solo_lower_leg_right_side" />
                        <geom pos="0 -0.008 -0.16" type="mesh" contype="0" conaffinity="0" group="1" rgba="0.8 0.8 0.8 1" mesh="solo_foot" />
                        <geom pos="0 -0.008 -0.16" type="mesh" rgba="0.8 0.8 0.8 1" mesh="solo_foot" />
                    </body>
                </body>
            </body>
        </body>
    </worldbody>
    <actuator>
        <position kp="8" ctrllimited="true" ctrlrange="-1.0 1.0" gear="1.5" joint="FL_HAA"/>
        <position kp="8" ctrllimited="true" ctrlrange="-1.0 1.0" gear="1" joint="FL_HFE"/>
        <position kp="8" ctrllimited="true" ctrlrange="-1.0 1.0" gear="1" joint="FL_KFE"/>
        <position kp="8" ctrllimited="true" ctrlrange="-1.0 1.0" gear="1.5" joint="FR_HAA"/>
        <position kp="8" ctrllimited="true" ctrlrange="-1.0 1.0" gear="1" joint="FR_HFE"/>
        <position kp="8" ctrllimited="true" ctrlrange="-1.0 1.0" gear="1" joint="FR_KFE"/>
        <position kp="8" ctrllimited="true" ctrlrange="-1.0 1.0" gear="1.5" joint="HL_HAA"/>
        <position kp="8" ctrllimited="true" ctrlrange="-1.0 1.0" gear="1" joint="HL_HFE"/>
        <position kp="8" ctrllimited="true" ctrlrange="-1.0 1.0" gear="1" joint="HL_KFE"/>
        <position kp="8" ctrllimited="true" ctrlrange="-1.0 1.0" gear="1.5" joint="HR_HAA"/>
        <position kp="8" ctrllimited="true" ctrlrange="-1.0 1.0" gear="1" joint="HR_HFE"/>
        <position kp="8" ctrllimited="true" ctrlrange="-1.0 1.0" gear="1" joint="HR_KFE"/>

        <velocity kv="0.06" ctrllimited="true" ctrlrange="-1.0 1.0" gear="1" joint="FL_HAA"/>
        <velocity kv="0.06" ctrllimited="true" ctrlrange="-1.0 1.0" gear="1" joint="FL_HFE"/>
        <velocity kv="0.06" ctrllimited="true" ctrlrange="-1.0 1.0" gear="1" joint="FL_KFE"/>
        <velocity kv="0.06" ctrllimited="true" ctrlrange="-1.0 1.0" gear="1" joint="FR_HAA"/>
        <velocity kv="0.06" ctrllimited="true" ctrlrange="-1.0 1.0" gear="1" joint="FR_HFE"/>
        <velocity kv="0.06" ctrllimited="true" ctrlrange="-1.0 1.0" gear="1" joint="FR_KFE"/>
        <velocity kv="0.06" ctrllimited="true" ctrlrange="-1.0 1.0" gear="1" joint="HL_HAA"/>
        <velocity kv="0.06" ctrllimited="true" ctrlrange="-1.0 1.0" gear="1" joint="HL_HFE"/>
        <velocity kv="0.06" ctrllimited="true" ctrlrange="-1.0 1.0" gear="1" joint="HL_KFE"/>
        <velocity kv="0.06" ctrllimited="true" ctrlrange="-1.0 1.0" gear="1" joint="HR_HAA"/>
        <velocity kv="0.06" ctrllimited="true" ctrlrange="-1.0 1.0" gear="1" joint="HR_HFE"/>
        <velocity kv="0.06" ctrllimited="true" ctrlrange="-1.0 1.0" gear="1" joint="HR_KFE"/>
  </actuator>
  <asset>
        <mesh name="solo_12_base" file="solo_12_base.stl" />
        <mesh name="solo12_hip_fe_fl" file="solo12_hip_fe_fl.stl" />
        <mesh name="solo_upper_leg_left_side" file="solo_upper_leg_left_side.stl" />
        <mesh name="solo_lower_leg_left_side" file="solo_lower_leg_left_side.stl" />
        <mesh name="solo_foot" file="solo_foot.stl" />
        <mesh name="solo12_hip_fe_fr" file="solo12_hip_fe_fr.stl" />
        <mesh name="solo_upper_leg_right_side" file="solo_upper_leg_right_side.stl" />
        <mesh name="solo_lower_leg_right_side" file="solo_lower_leg_right_side.stl" />
        <mesh name="solo12_hip_fe_hl" file="solo12_hip_fe_hl.stl" />
        <mesh name="solo12_hip_fe_hr" file="solo12_hip_fe_hr.stl" />
        <texture type="skybox" builtin="gradient" rgb1=".4 .5 .6" rgb2="0 0 0" width="100" height="100"/>
        <texture builtin="flat" height="1278" mark="cross" markrgb="1 1 1" name="texgeom" random="0.01" rgb1="0.8 0.6 0.4" rgb2="0.8 0.6 0.4" type="cube" width="127"/>
        <texture builtin="checker" height="100" name="texplane" rgb1="0 0 0" rgb2="0.8 0.8 0.8" type="2d" width="100"/>
        <material name="MatPlane" reflectance="0.5" shininess="1" specular="1" texrepeat="60 60" texture="texplane"/>
        <material name="geom" texture="texgeom" texuniform="true"/>
    </asset>
</mujoco>
